[2024-11-27T04:14:29.229+0000] {local_task_job_runner.py:120} INFO - ::group::Pre task execution logs
[2024-11-27T04:14:29.251+0000] {taskinstance.py:2076} INFO - Dependencies all met for dep_context=non-requeueable deps ti=<TaskInstance: amazon_recommendation_pipeline_elt.load_data scheduled__2024-11-26T00:00:00+00:00 [queued]>
[2024-11-27T04:14:29.257+0000] {taskinstance.py:2076} INFO - Dependencies all met for dep_context=requeueable deps ti=<TaskInstance: amazon_recommendation_pipeline_elt.load_data scheduled__2024-11-26T00:00:00+00:00 [queued]>
[2024-11-27T04:14:29.258+0000] {taskinstance.py:2306} INFO - Starting attempt 1 of 4
[2024-11-27T04:14:29.267+0000] {taskinstance.py:2330} INFO - Executing <Task(PythonOperator): load_data> on 2024-11-26 00:00:00+00:00
[2024-11-27T04:14:29.274+0000] {standard_task_runner.py:90} INFO - Running: ['***', 'tasks', 'run', 'amazon_recommendation_pipeline_elt', 'load_data', 'scheduled__2024-11-26T00:00:00+00:00', '--job-id', '94', '--raw', '--subdir', 'DAGS_FOLDER/amazon_recommendation_dag.py', '--cfg-path', '/tmp/tmpglu02bfz']
[2024-11-27T04:14:29.275+0000] {standard_task_runner.py:91} INFO - Job 94: Subtask load_data
[2024-11-27T04:14:29.276+0000] {logging_mixin.py:188} WARNING - /home/***/.local/lib/python3.12/site-packages/***/task/task_runner/standard_task_runner.py:61 DeprecationWarning: This process (pid=9309) is multi-threaded, use of fork() may lead to deadlocks in the child.
[2024-11-27T04:14:29.277+0000] {standard_task_runner.py:63} INFO - Started process 9315 to run task
[2024-11-27T04:14:29.313+0000] {task_command.py:426} INFO - Running <TaskInstance: amazon_recommendation_pipeline_elt.load_data scheduled__2024-11-26T00:00:00+00:00 [running]> on host bece637e0b85
[2024-11-27T04:14:29.386+0000] {taskinstance.py:2648} INFO - Exporting env vars: AIRFLOW_CTX_DAG_OWNER='***' AIRFLOW_CTX_DAG_ID='amazon_recommendation_pipeline_elt' AIRFLOW_CTX_TASK_ID='load_data' AIRFLOW_CTX_EXECUTION_DATE='2024-11-26T00:00:00+00:00' AIRFLOW_CTX_TRY_NUMBER='1' AIRFLOW_CTX_DAG_RUN_ID='scheduled__2024-11-26T00:00:00+00:00'
[2024-11-27T04:14:29.387+0000] {taskinstance.py:430} INFO - ::endgroup::
[2024-11-27T04:14:39.434+0000] {taskinstance.py:441} INFO - ::group::Post task execution logs
[2024-11-27T04:14:39.435+0000] {taskinstance.py:2905} ERROR - Task failed with exception
Traceback (most recent call last):
  File "/home/airflow/.local/lib/python3.12/site-packages/pymilvus/client/grpc_handler.py", line 149, in _wait_for_channel_ready
    grpc.channel_ready_future(self._channel).result(timeout=timeout)
  File "/home/airflow/.local/lib/python3.12/site-packages/grpc/_utilities.py", line 162, in result
    self._block(timeout)
  File "/home/airflow/.local/lib/python3.12/site-packages/grpc/_utilities.py", line 106, in _block
    raise grpc.FutureTimeoutError()
grpc.FutureTimeoutError

The above exception was the direct cause of the following exception:

Traceback (most recent call last):
  File "/home/airflow/.local/lib/python3.12/site-packages/airflow/models/taskinstance.py", line 465, in _execute_task
    result = _execute_callable(context=context, **execute_callable_kwargs)
             ^^^^^^^^^^^^^^^^^^^^^^^^^^^^^^^^^^^^^^^^^^^^^^^^^^^^^^^^^^^^^
  File "/home/airflow/.local/lib/python3.12/site-packages/airflow/models/taskinstance.py", line 432, in _execute_callable
    return execute_callable(context=context, **execute_callable_kwargs)
           ^^^^^^^^^^^^^^^^^^^^^^^^^^^^^^^^^^^^^^^^^^^^^^^^^^^^^^^^^^^^
  File "/home/airflow/.local/lib/python3.12/site-packages/airflow/models/baseoperator.py", line 401, in wrapper
    return func(self, *args, **kwargs)
           ^^^^^^^^^^^^^^^^^^^^^^^^^^^
  File "/home/airflow/.local/lib/python3.12/site-packages/airflow/operators/python.py", line 235, in execute
    return_value = self.execute_callable()
                   ^^^^^^^^^^^^^^^^^^^^^^^
  File "/home/airflow/.local/lib/python3.12/site-packages/airflow/operators/python.py", line 252, in execute_callable
    return self.python_callable(*self.op_args, **self.op_kwargs)
           ^^^^^^^^^^^^^^^^^^^^^^^^^^^^^^^^^^^^^^^^^^^^^^^^^^^^^
  File "/opt/airflow/dags/tasks/milvus_load_task.py", line 21, in load_to_milvus
    connections.connect(host=MILVUS_HOST, port=MILVUS_PORT)
  File "/home/airflow/.local/lib/python3.12/site-packages/pymilvus/orm/connections.py", line 451, in connect
    connect_milvus(**kwargs, user=user, password=password, token=token, db_name=db_name)
  File "/home/airflow/.local/lib/python3.12/site-packages/pymilvus/orm/connections.py", line 402, in connect_milvus
    gh._wait_for_channel_ready(timeout=timeout)
  File "/home/airflow/.local/lib/python3.12/site-packages/pymilvus/client/grpc_handler.py", line 152, in _wait_for_channel_ready
    raise MilvusException(
pymilvus.exceptions.MilvusException: <MilvusException: (code=2, message=Fail connecting to server on localhost:19530, illegal connection params or server unavailable)>
[2024-11-27T04:14:39.446+0000] {taskinstance.py:1206} INFO - Marking task as UP_FOR_RETRY. dag_id=amazon_recommendation_pipeline_elt, task_id=load_data, run_id=scheduled__2024-11-26T00:00:00+00:00, execution_date=20241126T000000, start_date=20241127T041429, end_date=20241127T041439
[2024-11-27T04:14:39.455+0000] {standard_task_runner.py:110} ERROR - Failed to execute job 94 for task load_data (<MilvusException: (code=2, message=Fail connecting to server on localhost:19530, illegal connection params or server unavailable)>; 9315)
[2024-11-27T04:14:39.477+0000] {local_task_job_runner.py:240} INFO - Task exited with return code 1
[2024-11-27T04:14:39.491+0000] {taskinstance.py:3503} INFO - 0 downstream tasks scheduled from follow-on schedule check
[2024-11-27T04:14:39.492+0000] {local_task_job_runner.py:222} INFO - ::endgroup::
